Workbook

Sheet z_Config
A1: URL file làm việc | B1: https://docs.google.com/spreadsheets/d/1J2A_OiWz7IeYsgafLDY3mIfZsG-xCNGhkNaSQkhicHg/edit
A2: Năm | B2: 2026
A3: URL file Database | B3: https://docs.google.com/spreadsheets/d/1i7-xLYiLHg60EqmCpfeA9B4Y0T-8YsgXk-_0qJ4eACo/edit

Sheet z_Trang
A1: =IMPORTRANGE('z_Config'!$B$1,"02_UI_UX!A3:N3")

Sheet z_TinhNang
A1: =IMPORTRANGE('z_Config'!$B$1,"03_Tính_năng!A3:N3")

Sheet z_TrangFull
A1: =IMPORTRANGE('z_Config'!$B$1,"02_UI_UX!A4:R68")

Sheet z_TNFull
A1: =IMPORTRANGE('z_Config'!$B$1,"03_Tính_năng!A4:T92")

Sheet z_Loi
A1: =IMPORTRANGE('z_Config'!$B$1,"05_Lỗi_Tester!A4:V606")

Sheet z_CV
A1: =IMPORTRANGE('z_Config'!$B$1,"01_Cong_viec_ngay!A4:P1004")

Sheet z_DB_DN
A1: =IMPORTRANGE('z_Config'!$B$3,"'HS DN'!D4:N970")

Sheet z_DB_HR
A1: =IMPORTRANGE('z_Config'!$B$3,"'HS HR'!D4:E966")

Sheet z_DB_UV
A1: =IMPORTRANGE('z_Config'!$B$3,"'HS ỨNG TUYỂN'!D5:D990")

Sheet z_DB_Tin
A1: =IMPORTRANGE('z_Config'!$B$3,"'Tin tuyển dụng'!C4:D1006")

Sheet 00_Hướng_dẫn
A1: BÁO CÁO TIẾN ĐỘ WEBSITE TIMVIEC123 — DÀNH CHO BAN GIÁM ĐỐC
A2: Số liệu đồng bộ live từ file làm việc QA và file Database. BGD chỉ xem, chọn kỳ ở sheet Tháng/Tuần.
A4: NGƯỜI DÙNG | C4: CÁCH SỬ DỤNG
A5: Ban Giám đốc | C5: Xem tiến độ trang/tính năng, tình trạng lỗi, database và nghiệm thu. Chọn Tháng/Tuần để lọc kỳ.
A6: Tester | C6: Cập nhật dữ liệu tại file làm việc; nhập Mục tiêu tại sheet 04_Mục_tiêu.
A7: Dev | C7: Cập nhật xử lý lỗi tại 06_RTM_Dev_Test của file làm việc.
A9: NGUYÊN TẮC TÍNH SỐ
A10: 1 | B10: Tiến độ trang = số trang Hoàn thành / tổng số trang (hiện 63). Tính năng / 88.
A11: 2 | B11: Số lỗi lấy toàn bộ từ 05_Lỗi_Tester. "Đang mở" = Open + Chưa gửi Dev; "Đã xử lý" = Fixed + Verified + Closed.
A12: 3 | B12: Mục tiêu nhập tại sheet 04_Mục_tiêu theo từng tháng/tuần (không cố định, không dùng chung).
A13: 4 | B13: Chi tiết theo Trang/Tính năng = mục có Ngày test gần nhất trong kỳ, trạng thái Hoàn thành/Kiểm tra lại.
A14: 5 | B14: Chỉ số Database lấy từ file Hồ sơ, đếm theo ngày đăng/tạo của kỳ.
A15: 6 | B15: Nghiệm thu theo người dùng: hành trình ĐẠT khi mọi bước Pass và không có lỗi Critical/High đang mở; vai trò ĐẠT khi mọi hành trình ĐẠT.
A17: KÍCH HOẠT KẾT NỐI (làm 1 lần)
A18: ① File làm việc QA | B18: =IMPORTRANGE('z_Config'!$B$1,"05_Lỗi_Tester!E4")
A19: ② File Database | B19: =IMPORTRANGE('z_Config'!$B$3,"'HS DN'!D3")
A20: → Nếu ô ① hoặc ② báo #REF!: bấm vào ô đó → "Cho phép truy cập / Allow access". Làm 1 lần cho mỗi ô.
A21: Trạng thái kết nối | B21: =IF(ISERROR('z_Trang'!$B$1),"⚠ Chưa kết nối file làm việc","✔ Đã kết nối")&" | "&IF(ISERROR('z_DB_DN'!$A:$A),"⚠ Chưa kết nối Database","✔ Database OK")
A23: LIÊN KẾT
A24: File làm việc (QA) | B24: https://docs.google.com/spreadsheets/d/1J2A_OiWz7IeYsgafLDY3mIfZsG-xCNGhkNaSQkhicHg/edit
A25: File Database (Hồ sơ) | B25: https://docs.google.com/spreadsheets/d/1i7-xLYiLHg60EqmCpfeA9B4Y0T-8YsgXk-_0qJ4eACo/edit

Sheet 01_Báo_cáo_Tháng
A1: BÁO CÁO TIẾN ĐỘ THEO THÁNG
A2: Chỉ số "trong tháng" lọc theo kỳ đã chọn; số Tổng quan là thời điểm hiện tại. Mục tiêu nhập tại sheet 04_Mục_tiêu (mỗi kỳ một dòng).
A4: Tháng báo cáo | B4: 8 | C4: Năm | D4: 2026 | E4: Ngày chốt | F4: =TODAY() | N4: =DATE(D4,B4,1) | O4: =EOMONTH(N4,0)
A6: KPI / CHỈ SỐ | B6: Mục tiêu kỳ | C6: Kết quả | D6: Tỷ lệ đạt | E6: Đạt KPI? | F6: Ghi chú
A7: I. KIỂM TRA WEBSITE
A8: 1. Trang hoàn thành | B8: =IFERROR(INDEX('04_Mục_tiêu'!$B$5:$L$16,MATCH($B$4,'04_Mục_tiêu'!$A$5:$A$16,0),1),"") | C8: ='z_Trang'!$D$1 | D8: =IFERROR(C8/B8,"") | E8: =IF(ISNUMBER(B8),IF(C8>=B8,"Đạt","Chưa đạt"),"Theo dõi") | F8: Hoàn thành / tổng số trang
A9: 2. Tính năng hoàn thành | B9: =IFERROR(INDEX('04_Mục_tiêu'!$B$5:$L$16,MATCH($B$4,'04_Mục_tiêu'!$A$5:$A$16,0),2),"") | C9: ='z_TinhNang'!$D$1 | D9: =IFERROR(C9/B9,"") | E9: =IF(ISNUMBER(B9),IF(C9>=B9,"Đạt","Chưa đạt"),"Theo dõi") | F9: Hoàn thành / 88 tính năng
A10: 3. Công việc hoàn thành trong tháng | B10: =IFERROR(INDEX('04_Mục_tiêu'!$B$5:$L$16,MATCH($B$4,'04_Mục_tiêu'!$A$5:$A$16,0),3),"") | C10: =COUNTIFS('z_CV'!$B:$B,">="&$N$4,'z_CV'!$B:$B,"<="&$O$4,'z_CV'!$O:$O,"Hoàn thành") | D10: =IFERROR(C10/B10,"") | E10: =IF(ISNUMBER(B10),IF(C10>=B10,"Đạt","Chưa đạt"),"Theo dõi") | F10: Nhật ký công việc theo ngày
A11: 4. Lỗi phát hiện trong tháng | B11: =IFERROR(INDEX('04_Mục_tiêu'!$B$5:$L$16,MATCH($B$4,'04_Mục_tiêu'!$A$5:$A$16,0),4),"") | C11: =COUNTIFS('z_Loi'!$Q:$Q,">="&$N$4,'z_Loi'!$Q:$Q,"<="&$O$4) | D11: =IFERROR(C11/B11,"") | E11: =IF(ISNUMBER(B11),IF(C11>=B11,"Đạt","Chưa đạt"),"Theo dõi") | F11: Theo Ngày phát hiện (05_Lỗi_Tester)
A12: II. HOÀN THIỆN WEBSITE
A13: 1. Lỗi đã xử lý (lũy kế) | B13: =IFERROR(INDEX('04_Mục_tiêu'!$B$5:$L$16,MATCH($B$4,'04_Mục_tiêu'!$A$5:$A$16,0),5),"") | C13: =(COUNTIF('z_Loi'!$U:$U,"Fixed")+COUNTIF('z_Loi'!$U:$U,"Verified")+COUNTIF('z_Loi'!$U:$U,"Closed")) | D13: =IFERROR(C13/B13,"") | E13: =IF(ISNUMBER(B13),IF(C13>=B13,"Đạt","Chưa đạt"),"Theo dõi") | F13: Fixed + Verified + Closed
A14: 2. Số Trang đã xử lý | B14: =IFERROR(INDEX('04_Mục_tiêu'!$B$5:$L$16,MATCH($B$4,'04_Mục_tiêu'!$A$5:$A$16,0),6),"") | C14: ='z_Trang'!$B$1-'z_Trang'!$L$1 | D14: =IFERROR(C14/B14,"") | E14: =IF(ISNUMBER(B14),IF(C14>=B14,"Đạt","Chưa đạt"),"Theo dõi") | F14: Đã kiểm thử = Tổng − Chưa kiểm tra
A15: 3. Số Tính năng đã xử lý | B15: =IFERROR(INDEX('04_Mục_tiêu'!$B$5:$L$16,MATCH($B$4,'04_Mục_tiêu'!$A$5:$A$16,0),7),"") | C15: ='z_TinhNang'!$B$1-'z_TinhNang'!$L$1 | D15: =IFERROR(C15/B15,"") | E15: =IF(ISNUMBER(B15),IF(C15>=B15,"Đạt","Chưa đạt"),"Theo dõi") | F15: Đã kiểm thử = Tổng − Chưa kiểm tra
A16: III. DATABASE (trong tháng)
A17: 1. DB Doanh nghiệp đã thêm | B17: =IFERROR(INDEX('04_Mục_tiêu'!$B$5:$L$16,MATCH($B$4,'04_Mục_tiêu'!$A$5:$A$16,0),8),"") | C17: =COUNTIFS('z_DB_DN'!$K:$K,">="&$N$4,'z_DB_DN'!$K:$K,"<="&$O$4) | D17: =IFERROR(C17/B17,"") | E17: =IF(ISNUMBER(B17),IF(C17>=B17,"Đạt","Chưa đạt"),"Theo dõi") | F17: Theo Ngày Đăng/Tạo
A18: 2. DB HR đã thêm | B18: =IFERROR(INDEX('04_Mục_tiêu'!$B$5:$L$16,MATCH($B$4,'04_Mục_tiêu'!$A$5:$A$16,0),9),"") | C18: =COUNTIFS('z_DB_HR'!$B:$B,">="&$N$4,'z_DB_HR'!$B:$B,"<="&$O$4) | D18: =IFERROR(C18/B18,"") | E18: =IF(ISNUMBER(B18),IF(C18>=B18,"Đạt","Chưa đạt"),"Theo dõi") | F18: Theo Ngày Đăng/Tạo
A19: 3. DB Ứng viên đã thêm | B19: =IFERROR(INDEX('04_Mục_tiêu'!$B$5:$L$16,MATCH($B$4,'04_Mục_tiêu'!$A$5:$A$16,0),10),"") | C19: =COUNTA('z_DB_UV'!$A:$A) | D19: =IFERROR(C19/B19,"") | E19: =IF(ISNUMBER(B19),IF(C19>=B19,"Đạt","Chưa đạt"),"Theo dõi") | F19: Theo tổng (chưa có cột ngày nhập)
A20: 4. Tin tuyển dụng đã đăng | B20: =IFERROR(INDEX('04_Mục_tiêu'!$B$5:$L$16,MATCH($B$4,'04_Mục_tiêu'!$A$5:$A$16,0),11),"") | C20: =COUNTIFS('z_DB_Tin'!$B:$B,">="&$N$4,'z_DB_Tin'!$B:$B,"<="&$O$4) | D20: =IFERROR(C20/B20,"") | E20: =IF(ISNUMBER(B20),IF(C20>=B20,"Đạt","Chưa đạt"),"Theo dõi") | F20: Theo Ngày viết
A22: TỔNG QUAN HIỆN TẠI (thời điểm xem)
A23: Chỉ số | B23: Số lượng | C23: Tổng | D23: Tỷ lệ
A24: I. KIỂM TRA WEBSITE
A25: Trang hoàn thành | B25: ='z_Trang'!$D$1 | C25: ='z_Trang'!$B$1 | D25: ='z_Trang'!$F$1
A26: Trang đang kiểm tra | B26: ='z_Trang'!$H$1 | C26: ='z_Trang'!$B$1 | D26: ='z_Trang'!$H$1/'z_Trang'!$B$1
A27: Trang cần kiểm tra lại | B27: ='z_Trang'!$J$1 | C27: ='z_Trang'!$B$1 | D27: ='z_Trang'!$J$1/'z_Trang'!$B$1
A28: Trang chưa kiểm tra | B28: ='z_Trang'!$L$1 | C28: ='z_Trang'!$B$1 | D28: ='z_Trang'!$L$1/'z_Trang'!$B$1
A29: Tính năng hoàn thành | B29: ='z_TinhNang'!$D$1 | C29: ='z_TinhNang'!$B$1 | D29: ='z_TinhNang'!$F$1
A30: Tính năng cần kiểm tra lại | B30: ='z_TinhNang'!$J$1 | C30: ='z_TinhNang'!$B$1 | D30: ='z_TinhNang'!$J$1/'z_TinhNang'!$B$1
A31: Tính năng chưa kiểm tra | B31: ='z_TinhNang'!$L$1 | C31: ='z_TinhNang'!$B$1 | D31: ='z_TinhNang'!$L$1/'z_TinhNang'!$B$1
A32: Tổng lỗi ghi nhận | B32: =COUNTA('z_Loi'!$E:$E)-1
A33: Lỗi đang mở (Open + Chưa gửi Dev) | B33: =(COUNTIF('z_Loi'!$U:$U,"Open")+COUNTIF('z_Loi'!$U:$U,"Chưa gửi Dev"))
A34: Lỗi Critical/High đang mở | B34: =(COUNTIFS('z_Loi'!$U:$U,"Open",'z_Loi'!$L:$L,"Critical")+COUNTIFS('z_Loi'!$U:$U,"Open",'z_Loi'!$L:$L,"High")+COUNTIFS('z_Loi'!$U:$U,"Chưa gửi Dev",'z_Loi'!$L:$L,"Critical")+COUNTIFS('z_Loi'!$U:$U,"Chưa gửi Dev",'z_Loi'!$L:$L,"High"))
A35: II. DATABASE (tổng đã thêm)
A36: DB Doanh nghiệp | B36: =COUNTA('z_DB_DN'!$A:$A)
A37: DB HR | B37: =COUNTA('z_DB_HR'!$A:$A)
A38: DB Ứng viên | B38: =COUNTA('z_DB_UV'!$A:$A)
A39: Tin tuyển dụng đã đăng | B39: =COUNTA('z_DB_Tin'!$A:$A)
A41: TÌNH TRẠNG XỬ LÝ LỖI (toàn bộ)
A42: Trạng thái | B42: Số lỗi | C42: Ý nghĩa
A43: Open | B43: =COUNTIF('z_Loi'!$U:$U,"Open") | C43: Lỗi đang mở, đã ghi nhận
A44: Chưa gửi Dev | B44: =COUNTIF('z_Loi'!$U:$U,"Chưa gửi Dev") | C44: Chưa chuyển Dev xử lý
...

Sheet 02_Báo_cáo_Tuần
A1: BÁO CÁO TIẾN ĐỘ THEO TUẦN
A2: Chỉ số "trong tuần" lọc theo kỳ đã chọn; số Tổng quan là thời điểm hiện tại. Mục tiêu nhập tại sheet 04_Mục_tiêu (mỗi kỳ một dòng).
A4: Tháng | B4: 8 | C4: Tuần | D4: 2 | E4: Năm | F4: 2026 | N4: =DATE(F4,B4,(D4-1)*7+1) | O4: =MIN(EOMONTH(DATE(F4,B4,1),0),DATE(F4,B4,D4*7))
A5: Từ ngày | B5: =N4 | C5: Đến ngày | D5: =O4 | F5: =IF(ISERROR('z_Trang'!$B$1),"⚠ Chưa kết nối","✔ Đã kết nối")
A7: KPI / CHỈ SỐ | B7: Mục tiêu kỳ | C7: Kết quả | D7: Tỷ lệ đạt | E7: Đạt KPI? | F7: Ghi chú
A8: I. KIỂM TRA WEBSITE
A9: 1. Trang hoàn thành | B9: =IFERROR(INDEX('04_Mục_tiêu'!$D$20:$N$79,MATCH($B$4*10+$D$4,'04_Mục_tiêu'!$C$20:$C$79,0),1),"") | C9: ='z_Trang'!$D$1 | D9: =IFERROR(C9/B9,"") | E9: =IF(ISNUMBER(B9),IF(C9>=B9,"Đạt","Chưa đạt"),"Theo dõi") | F9: Hoàn thành / tổng số trang
A10: 2. Tính năng hoàn thành | B10: =IFERROR(INDEX('04_Mục_tiêu'!$D$20:$N$79,MATCH($B$4*10+$D$4,'04_Mục_tiêu'!$C$20:$C$79,0),2),"") | C10: ='z_TinhNang'!$D$1 | D10: =IFERROR(C10/B10,"") | E10: =IF(ISNUMBER(B10),IF(C10>=B10,"Đạt","Chưa đạt"),"Theo dõi") | F10: Hoàn thành / 88 tính năng
A11: 3. Công việc hoàn thành trong tuần | B11: =IFERROR(INDEX('04_Mục_tiêu'!$D$20:$N$79,MATCH($B$4*10+$D$4,'04_Mục_tiêu'!$C$20:$C$79,0),3),"") | C11: =COUNTIFS('z_CV'!$B:$B,">="&$N$4,'z_CV'!$B:$B,"<="&$O$4,'z_CV'!$O:$O,"Hoàn thành") | D11: =IFERROR(C11/B11,"") | E11: =IF(ISNUMBER(B11),IF(C11>=B11,"Đạt","Chưa đạt"),"Theo dõi") | F11: Nhật ký công việc theo ngày
A12: 4. Lỗi phát hiện trong tuần | B12: =IFERROR(INDEX('04_Mục_tiêu'!$D$20:$N$79,MATCH($B$4*10+$D$4,'04_Mục_tiêu'!$C$20:$C$79,0),4),"") | C12: =COUNTIFS('z_Loi'!$Q:$Q,">="&$N$4,'z_Loi'!$Q:$Q,"<="&$O$4) | D12: =IFERROR(C12/B12,"") | E12: =IF(ISNUMBER(B12),IF(C12>=B12,"Đạt","Chưa đạt"),"Theo dõi") | F12: Theo Ngày phát hiện (05_Lỗi_Tester)
A13: II. HOÀN THIỆN WEBSITE
A14: 1. Lỗi đã xử lý (lũy kế) | B14: =IFERROR(INDEX('04_Mục_tiêu'!$D$20:$N$79,MATCH($B$4*10+$D$4,'04_Mục_tiêu'!$C$20:$C$79,0),5),"") | C14: =(COUNTIF('z_Loi'!$U:$U,"Fixed")+COUNTIF('z_Loi'!$U:$U,"Verified")+COUNTIF('z_Loi'!$U:$U,"Closed")) | D14: =IFERROR(C14/B14,"") | E14: =IF(ISNUMBER(B14),IF(C14>=B14,"Đạt","Chưa đạt"),"Theo dõi") | F14: Fixed + Verified + Closed
A15: 2. Số Trang đã xử lý | B15: =IFERROR(INDEX('04_Mục_tiêu'!$D$20:$N$79,MATCH($B$4*10+$D$4,'04_Mục_tiêu'!$C$20:$C$79,0),6),"") | C15: ='z_Trang'!$B$1-'z_Trang'!$L$1 | D15: =IFERROR(C15/B15,"") | E15: =IF(ISNUMBER(B15),IF(C15>=B15,"Đạt","Chưa đạt"),"Theo dõi") | F15: Đã kiểm thử = Tổng − Chưa kiểm tra
A16: 3. Số Tính năng đã xử lý | B16: =IFERROR(INDEX('04_Mục_tiêu'!$D$20:$N$79,MATCH($B$4*10+$D$4,'04_Mục_tiêu'!$C$20:$C$79,0),7),"") | C16: ='z_TinhNang'!$B$1-'z_TinhNang'!$L$1 | D16: =IFERROR(C16/B16,"") | E16: =IF(ISNUMBER(B16),IF(C16>=B16,"Đạt","Chưa đạt"),"Theo dõi") | F16: Đã kiểm thử = Tổng − Chưa kiểm tra
A17: III. DATABASE (trong tuần)
A18: 1. DB Doanh nghiệp đã thêm | B18: =IFERROR(INDEX('04_Mục_tiêu'!$D$20:$N$79,MATCH($B$4*10+$D$4,'04_Mục_tiêu'!$C$20:$C$79,0),8),"") | C18: =COUNTIFS('z_DB_DN'!$K:$K,">="&$N$4,'z_DB_DN'!$K:$K,"<="&$O$4) | D18: =IFERROR(C18/B18,"") | E18: =IF(ISNUMBER(B18),IF(C18>=B18,"Đạt","Chưa đạt"),"Theo dõi") | F18: Theo Ngày Đăng/Tạo
A19: 2. DB HR đã thêm | B19: =IFERROR(INDEX('04_Mục_tiêu'!$D$20:$N$79,MATCH($B$4*10+$D$4,'04_Mục_tiêu'!$C$20:$C$79,0),9),"") | C19: =COUNTIFS('z_DB_HR'!$B:$B,">="&$N$4,'z_DB_HR'!$B:$B,"<="&$O$4) | D19: =IFERROR(C19/B19,"") | E19: =IF(ISNUMBER(B19),IF(C19>=B19,"Đạt","Chưa đạt"),"Theo dõi") | F19: Theo Ngày Đăng/Tạo
A20: 3. DB Ứng viên đã thêm | B20: =IFERROR(INDEX('04_Mục_tiêu'!$D$20:$N$79,MATCH($B$4*10+$D$4,'04_Mục_tiêu'!$C$20:$C$79,0),10),"") | C20: =COUNTA('z_DB_UV'!$A:$A) | D20: =IFERROR(C20/B20,"") | E20: =IF(ISNUMBER(B20),IF(C20>=B20,"Đạt","Chưa đạt"),"Theo dõi") | F20: Theo tổng (chưa có cột ngày nhập)
A21: 4. Tin tuyển dụng đã đăng | B21: =IFERROR(INDEX('04_Mục_tiêu'!$D$20:$N$79,MATCH($B$4*10+$D$4,'04_Mục_tiêu'!$C$20:$C$79,0),11),"") | C21: =COUNTIFS('z_DB_Tin'!$B:$B,">="&$N$4,'z_DB_Tin'!$B:$B,"<="&$O$4) | D21: =IFERROR(C21/B21,"") | E21: =IF(ISNUMBER(B21),IF(C21>=B21,"Đạt","Chưa đạt"),"Theo dõi") | F21: Theo Ngày viết
A23: TỔNG QUAN HIỆN TẠI (thời điểm xem)
A24: Chỉ số | B24: Số lượng | C24: Tổng | D24: Tỷ lệ
A25: I. KIỂM TRA WEBSITE
A26: Trang hoàn thành | B26: ='z_Trang'!$D$1 | C26: ='z_Trang'!$B$1 | D26: ='z_Trang'!$F$1
A27: Trang đang kiểm tra | B27: ='z_Trang'!$H$1 | C27: ='z_Trang'!$B$1 | D27: ='z_Trang'!$H$1/'z_Trang'!$B$1
A28: Trang cần kiểm tra lại | B28: ='z_Trang'!$J$1 | C28: ='z_Trang'!$B$1 | D28: ='z_Trang'!$J$1/'z_Trang'!$B$1
A29: Trang chưa kiểm tra | B29: ='z_Trang'!$L$1 | C29: ='z_Trang'!$B$1 | D29: ='z_Trang'!$L$1/'z_Trang'!$B$1
A30: Tính năng hoàn thành | B30: ='z_TinhNang'!$D$1 | C30: ='z_TinhNang'!$B$1 | D30: ='z_TinhNang'!$F$1
A31: Tính năng cần kiểm tra lại | B31: ='z_TinhNang'!$J$1 | C31: ='z_TinhNang'!$B$1 | D31: ='z_TinhNang'!$J$1/'z_TinhNang'!$B$1
A32: Tính năng chưa kiểm tra | B32: ='z_TinhNang'!$L$1 | C32: ='z_TinhNang'!$B$1 | D32: ='z_TinhNang'!$L$1/'z_TinhNang'!$B$1
A33: Tổng lỗi ghi nhận | B33: =COUNTA('z_Loi'!$E:$E)-1
A34: Lỗi đang mở (Open + Chưa gửi Dev) | B34: =(COUNTIF('z_Loi'!$U:$U,"Open")+COUNTIF('z_Loi'!$U:$U,"Chưa gửi Dev"))
A35: Lỗi Critical/High đang mở | B35: =(COUNTIFS('z_Loi'!$U:$U,"Open",'z_Loi'!$L:$L,"Critical")+COUNTIFS('z_Loi'!$U:$U,"Open",'z_Loi'!$L:$L,"High")+COUNTIFS('z_Loi'!$U:$U,"Chưa gửi Dev",'z_Loi'!$L:$L,"Critical")+COUNTIFS('z_Loi'!$U:$U,"Chưa gửi Dev",'z_Loi'!$L:$L,"High"))
A36: II. DATABASE (tổng đã thêm)
A37: DB Doanh nghiệp | B37: =COUNTA('z_DB_DN'!$A:$A)
A38: DB HR | B38: =COUNTA('z_DB_HR'!$A:$A)
A39: DB Ứng viên | B39: =COUNTA('z_DB_UV'!$A:$A)
A40: Tin tuyển dụng đã đăng | B40: =COUNTA('z_DB_Tin'!$A:$A)
A42: TÌNH TRẠNG XỬ LÝ LỖI (toàn bộ)
A43: Trạng thái | B43: Số lỗi | C43: Ý nghĩa
A44: Open | B44: =COUNTIF('z_Loi'!$U:$U,"Open") | C44: Lỗi đang mở, đã ghi nhận
...

Sheet 03_Nghiệm_thu
A1: BIÊN BẢN NGHIỆM THU THEO NGƯỜI DÙNG — WEBSITE TIMVIEC123
A2: Nghiệm thu theo góc nhìn người dùng: mỗi VAI TRÒ phải đi hết được các HÀNH TRÌNH chính. Tester chỉ nhập ô nền vàng ở mục IV; mục I–III tự tính. Mức độ/trạng thái lỗi tra live từ 05_Lỗi_Tester theo BUG_ID.
A4: Kỳ nghiệm thu | B4: Tháng 8 | C4: Ngày lập | D4: =TODAY() | E4: Người lập | I4: Môi trường | J4: Production
A6: I. TỔNG HỢP THEO VAI TRÒ NGƯỜI DÙNG (tự tính từ mục III–IV)
A7: Vai trò | B7: Số hành trình | C7: Hành trình ĐẠT | D7: Tổng số bước | E7: Pass | F7: Fail | G7: Blocked | H7: Chưa test | I7: % Pass | J7: Lỗi C/H đang chặn | K7: Kết luận | L7: Ghi chú / Người duyệt
A8: Khách vãng lai | B8: =COUNTIF($B$35:$B$49,$A8) | C8: =COUNTIFS($B$35:$B$49,$A8,$K$35:$K$49,"ĐẠT") | D8: =COUNTIFS($C$54:$C$114,$A8,$A$54:$A$114,"<>") | E8: =COUNTIFS($C$54:$C$114,$A8,$G$54:$G$114,"Pass") | F8: =COUNTIFS($C$54:$C$114,$A8,$G$54:$G$114,"Fail") | G8: =COUNTIFS($C$54:$C$114,$A8,$G$54:$G$114,"Blocked") | H8: =D8-E8-F8-G8 | I8: =IF(D8=0,"",E8/D8) | J8: =COUNTIFS($C$54:$C$114,$A8,$K$54:$K$114,"CHẶN") | K8: =IF(B8=0,"—",IF(AND(C8=B8,J8=0),"ĐẠT",IF(OR(F8+G8>0,J8>0),"CHƯA ĐẠT","ĐANG TEST")))
A9: Ứng viên | B9: =COUNTIF($B$35:$B$49,$A9) | C9: =COUNTIFS($B$35:$B$49,$A9,$K$35:$K$49,"ĐẠT") | D9: =COUNTIFS($C$54:$C$114,$A9,$A$54:$A$114,"<>") | E9: =COUNTIFS($C$54:$C$114,$A9,$G$54:$G$114,"Pass") | F9: =COUNTIFS($C$54:$C$114,$A9,$G$54:$G$114,"Fail") | G9: =COUNTIFS($C$54:$C$114,$A9,$G$54:$G$114,"Blocked") | H9: =D9-E9-F9-G9 | I9: =IF(D9=0,"",E9/D9) | J9: =COUNTIFS($C$54:$C$114,$A9,$K$54:$K$114,"CHẶN") | K9: =IF(B9=0,"—",IF(AND(C9=B9,J9=0),"ĐẠT",IF(OR(F9+G9>0,J9>0),"CHƯA ĐẠT","ĐANG TEST")))
A10: Nhà tuyển dụng (DN) | B10: =COUNTIF($B$35:$B$49,$A10) | C10: =COUNTIFS($B$35:$B$49,$A10,$K$35:$K$49,"ĐẠT") | D10: =COUNTIFS($C$54:$C$114,$A10,$A$54:$A$114,"<>") | E10: =COUNTIFS($C$54:$C$114,$A10,$G$54:$G$114,"Pass") | F10: =COUNTIFS($C$54:$C$114,$A10,$G$54:$G$114,"Fail") | G10: =COUNTIFS($C$54:$C$114,$A10,$G$54:$G$114,"Blocked") | H10: =D10-E10-F10-G10 | I10: =IF(D10=0,"",E10/D10) | J10: =COUNTIFS($C$54:$C$114,$A10,$K$54:$K$114,"CHẶN") | K10: =IF(B10=0,"—",IF(AND(C10=B10,J10=0),"ĐẠT",IF(OR(F10+G10>0,J10>0),"CHƯA ĐẠT","ĐANG TEST")))
A11: HR | B11: =COUNTIF($B$35:$B$49,$A11) | C11: =COUNTIFS($B$35:$B$49,$A11,$K$35:$K$49,"ĐẠT") | D11: =COUNTIFS($C$54:$C$114,$A11,$A$54:$A$114,"<>") | E11: =COUNTIFS($C$54:$C$114,$A11,$G$54:$G$114,"Pass") | F11: =COUNTIFS($C$54:$C$114,$A11,$G$54:$G$114,"Fail") | G11: =COUNTIFS($C$54:$C$114,$A11,$G$54:$G$114,"Blocked") | H11: =D11-E11-F11-G11 | I11: =IF(D11=0,"",E11/D11) | J11: =COUNTIFS($C$54:$C$114,$A11,$K$54:$K$114,"CHẶN") | K11: =IF(B11=0,"—",IF(AND(C11=B11,J11=0),"ĐẠT",IF(OR(F11+G11>0,J11>0),"CHƯA ĐẠT","ĐANG TEST")))
A12: Quản trị viên | B12: =COUNTIF($B$35:$B$49,$A12) | C12: =COUNTIFS($B$35:$B$49,$A12,$K$35:$K$49,"ĐẠT") | D12: =COUNTIFS($C$54:$C$114,$A12,$A$54:$A$114,"<>") | E12: =COUNTIFS($C$54:$C$114,$A12,$G$54:$G$114,"Pass") | F12: =COUNTIFS($C$54:$C$114,$A12,$G$54:$G$114,"Fail") | G12: =COUNTIFS($C$54:$C$114,$A12,$G$54:$G$114,"Blocked") | H12: =D12-E12-F12-G12 | I12: =IF(D12=0,"",E12/D12) | J12: =COUNTIFS($C$54:$C$114,$A12,$K$54:$K$114,"CHẶN") | K12: =IF(B12=0,"—",IF(AND(C12=B12,J12=0),"ĐẠT",IF(OR(F12+G12>0,J12>0),"CHƯA ĐẠT","ĐANG TEST")))
A13: TỔNG | B13: =SUM(B8:B12) | C13: =SUM(C8:C12) | D13: =SUM(D8:D12) | E13: =SUM(E8:E12) | F13: =SUM(F8:F12) | G13: =SUM(G8:G12) | H13: =SUM(H8:H12) | I13: =IF(D13=0,"",E13/D13) | J13: =SUM(J8:J12) | K13: =IF(B13=0,"—",IF(AND(C13=B13,J13=0),"ĐẠT",IF(OR(F13+G13>0,J13>0),"CHƯA ĐẠT","ĐANG TEST")))
A15: KẾT LUẬN (tự động) | C15: =IF(B13=0,"Chưa có hành trình nghiệm thu",IF(K13="ĐẠT","✔ ĐỦ ĐIỀU KIỆN NGHIỆM THU — "&C13&"/"&B13&" hành trình đạt, không còn lỗi Critical/High chặn","✖ CHƯA ĐỦ ĐIỀU KIỆN — "&C13&"/"&B13&" hành trình đạt; "&F13&" bước Fail, "&G13&" Blocked, "&H13&" chưa test; "&J13&" lỗi Critical/High đang chặn"))
A16: QUYẾT ĐỊNH BGD | F16: Điều kiện / ngoại lệ
A17: Điều kiện ĐẠT: mọi bước của hành trình là Pass và không có BUG_ID mức Critical/High còn Open/Chưa gửi Dev. Ngoại lệ phải ghi rõ lý do và người duyệt.
A19: II. CHẤT LƯỢNG KỸ THUẬT (live từ file QA)
A20: Hạng mục | B20: Phạm vi | C20: Tổng | D20: Hoàn thành | E20: Tỷ lệ | F20: Critical/High mở | G20: Kết luận | H20: Ghi chú
A21: UI/UX | B21: Trang website | C21: ='z_Trang'!$B$1 | D21: ='z_Trang'!$D$1 | E21: ='z_Trang'!$F$1 | F21: =(COUNTIFS('z_Loi'!$U:$U,"Open",'z_Loi'!$L:$L,"Critical")+COUNTIFS('z_Loi'!$U:$U,"Open",'z_Loi'!$L:$L,"High")+COUNTIFS('z_Loi'!$U:$U,"Chưa gửi Dev",'z_Loi'!$L:$L,"Critical")+COUNTIFS('z_Loi'!$U:$U,"Chưa gửi Dev",'z_Loi'!$L:$L,"High"))
A22: Chức năng | B22: 88 tính năng | C22: ='z_TinhNang'!$B$1 | D22: ='z_TinhNang'!$D$1 | E22: ='z_TinhNang'!$F$1 | F22: =(COUNTIFS('z_Loi'!$U:$U,"Open",'z_Loi'!$L:$L,"Critical")+COUNTIFS('z_Loi'!$U:$U,"Open",'z_Loi'!$L:$L,"High")+COUNTIFS('z_Loi'!$U:$U,"Chưa gửi Dev",'z_Loi'!$L:$L,"Critical")+COUNTIFS('z_Loi'!$U:$U,"Chưa gửi Dev",'z_Loi'!$L:$L,"High"))
A23: Responsive | B23: YC_87 + lỗi responsive | F23: =COUNTIF('z_Loi'!$K:$K,"*Responsive*")
A24: Bảo mật | B24: Test Case Security | F24: =COUNTIF('z_Loi'!$K:$K,"*Security*")
A25: Dữ liệu | B25: Test Case API/Database
A27: NGƯỜI LẬP (Tester) | D27: QA LEAD | F27: ĐẠI DIỆN DEV | K27: BAN GIÁM ĐỐC
A28: (Ký, ghi rõ họ tên) | D28: (Ký, ghi rõ họ tên) | F28: (Ký, ghi rõ họ tên) | K28: (Ký, ghi rõ họ tên)
A32: III. DANH SÁCH HÀNH TRÌNH NGƯỜI DÙNG (kết luận tự tính từ mục IV)
A33: Thêm hành trình mới vào các dòng trống (nhập Mã HT, Vai trò, Tên). Mã HT phải khớp với cột Mã HT ở mục IV.
A34: Mã HT | B34: Vai trò | C34: Tên hành trình | E34: Số bước | F34: Pass | G34: Fail | H34: Blocked | I34: % Pass | J34: Lỗi C/H chặn | K34: Kết luận | L34: Ghi chú
A35: KV-01 | B35: Khách vãng lai | C35: Tìm & xem việc làm khi chưa đăng nhập | E35: =IF($A35="","",COUNTIF($A$54:$A$114,$A35)) | F35: =IF($A35="","",COUNTIFS($A$54:$A$114,$A35,$G$54:$G$114,"Pass")) | G35: =IF($A35="","",COUNTIFS($A$54:$A$114,$A35,$G$54:$G$114,"Fail")) | H35: =IF($A35="","",COUNTIFS($A$54:$A$114,$A35,$G$54:$G$114,"Blocked")) | I35: =IF(OR($A35="",N(E35)=0),"",F35/E35) | J35: =IF($A35="","",COUNTIFS($A$54:$A$114,$A35,$K$54:$K$114,"CHẶN")) | K35: =IF($A35="","",IF(E35=0,"Chưa có bước",IF(J35>0,"CHƯA ĐẠT",IF(F35=E35,"ĐẠT",IF(G35+H35>0,"CHƯA ĐẠT","ĐANG TEST")))))
A36: UV-01 | B36: Ứng viên | C36: Đăng ký & đăng nhập | E36: =IF($A36="","",COUNTIF($A$54:$A$114,$A36)) | F36: =IF($A36="","",COUNTIFS($A$54:$A$114,$A36,$G$54:$G$114,"Pass")) | G36: =IF($A36="","",COUNTIFS($A$54:$A$114,$A36,$G$54:$G$114,"Fail")) | H36: =IF($A36="","",COUNTIFS($A$54:$A$114,$A36,$G$54:$G$114,"Blocked")) | I36: =IF(OR($A36="",N(E36)=0),"",F36/E36) | J36: =IF($A36="","",COUNTIFS($A$54:$A$114,$A36,$K$54:$K$114,"CHẶN")) | K36: =IF($A36="","",IF(E36=0,"Chưa có bước",IF(J36>0,"CHƯA ĐẠT",IF(F36=E36,"ĐẠT",IF(G36+H36>0,"CHƯA ĐẠT","ĐANG TEST")))))
A37: UV-02 | B37: Ứng viên | C37: Tạo hồ sơ & CV | E37: =IF($A37="","",COUNTIF($A$54:$A$114,$A37)) | F37: =IF($A37="","",COUNTIFS($A$54:$A$114,$A37,$G$54:$G$114,"Pass")) | G37: =IF($A37="","",COUNTIFS($A$54:$A$114,$A37,$G$54:$G$114,"Fail")) | H37: =IF($A37="","",COUNTIFS($A$54:$A$114,$A37,$G$54:$G$114,"Blocked")) | I37: =IF(OR($A37="",N(E37)=0),"",F37/E37) | J37: =IF($A37="","",COUNTIFS($A$54:$A$114,$A37,$K$54:$K$114,"CHẶN")) | K37: =IF($A37="","",IF(E37=0,"Chưa có bước",IF(J37>0,"CHƯA ĐẠT",IF(F37=E37,"ĐẠT",IF(G37+H37>0,"CHƯA ĐẠT","ĐANG TEST")))))
A38: UV-03 | B38: Ứng viên | C38: Tìm việc & ứng tuyển | E38: =IF($A38="","",COUNTIF($A$54:$A$114,$A38)) | F38: =IF($A38="","",COUNTIFS($A$54:$A$114,$A38,$G$54:$G$114,"Pass")) | G38: =IF($A38="","",COUNTIFS($A$54:$A$114,$A38,$G$54:$G$114,"Fail")) | H38: =IF($A38="","",COUNTIFS($A$54:$A$114,$A38,$G$54:$G$114,"Blocked")) | I38: =IF(OR($A38="",N(E38)=0),"",F38/E38) | J38: =IF($A38="","",COUNTIFS($A$54:$A$114,$A38,$K$54:$K$114,"CHẶN")) | K38: =IF($A38="","",IF(E38=0,"Chưa có bước",IF(J38>0,"CHƯA ĐẠT",IF(F38=E38,"ĐẠT",IF(G38+H38>0,"CHƯA ĐẠT","ĐANG TEST")))))
A39: NTD-01 | B39: Nhà tuyển dụng (DN) | C39: Đăng ký doanh nghiệp & xác thực | E39: =IF($A39="","",COUNTIF($A$54:$A$114,$A39)) | F39: =IF($A39="","",COUNTIFS($A$54:$A$114,$A39,$G$54:$G$114,"Pass")) | G39: =IF($A39="","",COUNTIFS($A$54:$A$114,$A39,$G$54:$G$114,"Fail")) | H39: =IF($A39="","",COUNTIFS($A$54:$A$114,$A39,$G$54:$G$114,"Blocked")) | I39: =IF(OR($A39="",N(E39)=0),"",F39/E39) | J39: =IF($A39="","",COUNTIFS($A$54:$A$114,$A39,$K$54:$K$114,"CHẶN")) | K39: =IF($A39="","",IF(E39=0,"Chưa có bước",IF(J39>0,"CHƯA ĐẠT",IF(F39=E39,"ĐẠT",IF(G39+H39>0,"CHƯA ĐẠT","ĐANG TEST")))))
A40: NTD-02 | B40: Nhà tuyển dụng (DN) | C40: Đăng & quản lý tin tuyển dụng | E40: =IF($A40="","",COUNTIF($A$54:$A$114,$A40)) | F40: =IF($A40="","",COUNTIFS($A$54:$A$114,$A40,$G$54:$G$114,"Pass")) | G40: =IF($A40="","",COUNTIFS($A$54:$A$114,$A40,$G$54:$G$114,"Fail")) | H40: =IF($A40="","",COUNTIFS($A$54:$A$114,$A40,$G$54:$G$114,"Blocked")) | I40: =IF(OR($A40="",N(E40)=0),"",F40/E40) | J40: =IF($A40="","",COUNTIFS($A$54:$A$114,$A40,$K$54:$K$114,"CHẶN")) | K40: =IF($A40="","",IF(E40=0,"Chưa có bước",IF(J40>0,"CHƯA ĐẠT",IF(F40=E40,"ĐẠT",IF(G40+H40>0,"CHƯA ĐẠT","ĐANG TEST")))))
A41: NTD-03 | B41: Nhà tuyển dụng (DN) | C41: Nhận & xử lý hồ sơ ứng viên | E41: =IF($A41="","",COUNTIF($A$54:$A$114,$A41)) | F41: =IF($A41="","",COUNTIFS($A$54:$A$114,$A41,$G$54:$G$114,"Pass")) | G41: =IF($A41="","",COUNTIFS($A$54:$A$114,$A41,$G$54:$G$114,"Fail")) | H41: =IF($A41="","",COUNTIFS($A$54:$A$114,$A41,$G$54:$G$114,"Blocked")) | I41: =IF(OR($A41="",N(E41)=0),"",F41/E41) | J41: =IF($A41="","",COUNTIFS($A$54:$A$114,$A41,$K$54:$K$114,"CHẶN")) | K41: =IF($A41="","",IF(E41=0,"Chưa có bước",IF(J41>0,"CHƯA ĐẠT",IF(F41=E41,"ĐẠT",IF(G41+H41>0,"CHƯA ĐẠT","ĐANG TEST")))))
A42: HR-01 | B42: HR | C42: Tài khoản HR của doanh nghiệp | E42: =IF($A42="","",COUNTIF($A$54:$A$114,$A42)) | F42: =IF($A42="","",COUNTIFS($A$54:$A$114,$A42,$G$54:$G$114,"Pass")) | G42: =IF($A42="","",COUNTIFS($A$54:$A$114,$A42,$G$54:$G$114,"Fail")) | H42: =IF($A42="","",COUNTIFS($A$54:$A$114,$A42,$G$54:$G$114,"Blocked")) | I42: =IF(OR($A42="",N(E42)=0),"",F42/E42) | J42: =IF($A42="","",COUNTIFS($A$54:$A$114,$A42,$K$54:$K$114,"CHẶN")) | K42: =IF($A42="","",IF(E42=0,"Chưa có bước",IF(J42>0,"CHƯA ĐẠT",IF(F42=E42,"ĐẠT",IF(G42+H42>0,"CHƯA ĐẠT","ĐANG TEST")))))
A43: AD-01 | B43: Quản trị viên | C43: Kiểm duyệt & vận hành | E43: =IF($A43="","",COUNTIF($A$54:$A$114,$A43)) | F43: =IF($A43="","",COUNTIFS($A$54:$A$114,$A43,$G$54:$G$114,"Pass")) | G43: =IF($A43="","",COUNTIFS($A$54:$A$114,$A43,$G$54:$G$114,"Fail")) | H43: =IF($A43="","",COUNTIFS($A$54:$A$114,$A43,$G$54:$G$114,"Blocked")) | I43: =IF(OR($A43="",N(E43)=0),"",F43/E43) | J43: =IF($A43="","",COUNTIFS($A$54:$A$114,$A43,$K$54:$K$114,"CHẶN")) | K43: =IF($A43="","",IF(E43=0,"Chưa có bước",IF(J43>0,"CHƯA ĐẠT",IF(F43=E43,"ĐẠT",IF(G43+H43>0,"CHƯA ĐẠT","ĐANG TEST")))))
E44: =IF($A44="","",COUNTIF($A$54:$A$114,$A44)) | F44: =IF($A44="","",COUNTIFS($A$54:$A$114,$A44,$G$54:$G$114,"Pass")) | G44: =IF($A44="","",COUNTIFS($A$54:$A$114,$A44,$G$54:$G$114,"Fail")) | H44: =IF($A44="","",COUNTIFS($A$54:$A$114,$A44,$G$54:$G$114,"Blocked")) | I44: =IF(OR($A44="",N(E44)=0),"",F44/E44) | J44: =IF($A44="","",COUNTIFS($A$54:$A$114,$A44,$K$54:$K$114,"CHẶN")) | K44: =IF($A44="","",IF(E44=0,"Chưa có bước",IF(J44>0,"CHƯA ĐẠT",IF(F44=E44,"ĐẠT",IF(G44+H44>0,"CHƯA ĐẠT","ĐANG TEST")))))
E45: =IF($A45="","",COUNTIF($A$54:$A$114,$A45)) | F45: =IF($A45="","",COUNTIFS($A$54:$A$114,$A45,$G$54:$G$114,"Pass")) | G45: =IF($A45="","",COUNTIFS($A$54:$A$114,$A45,$G$54:$G$114,"Fail")) | H45: =IF($A45="","",COUNTIFS($A$54:$A$114,$A45,$G$54:$G$114,"Blocked")) | I45: =IF(OR($A45="",N(E45)=0),"",F45/E45) | J45: =IF($A45="","",COUNTIFS($A$54:$A$114,$A45,$K$54:$K$114,"CHẶN")) | K45: =IF($A45="","",IF(E45=0,"Chưa có bước",IF(J45>0,"CHƯA ĐẠT",IF(F45=E45,"ĐẠT",IF(G45+H45>0,"CHƯA ĐẠT","ĐANG TEST")))))
E46: =IF($A46="","",COUNTIF($A$54:$A$114,$A46)) | F46: =IF($A46="","",COUNTIFS($A$54:$A$114,$A46,$G$54:$G$114,"Pass")) | G46: =IF($A46="","",COUNTIFS($A$54:$A$114,$A46,$G$54:$G$114,"Fail")) | H46: =IF($A46="","",COUNTIFS($A$54:$A$114,$A46,$G$54:$G$114,"Blocked")) | I46: =IF(OR($A46="",N(E46)=0),"",F46/E46) | J46: =IF($A46="","",COUNTIFS($A$54:$A$114,$A46,$K$54:$K$114,"CHẶN")) | K46: =IF($A46="","",IF(E46=0,"Chưa có bước",IF(J46>0,"CHƯA ĐẠT",IF(F46=E46,"ĐẠT",IF(G46+H46>0,"CHƯA ĐẠT","ĐANG TEST")))))
E47: =IF($A47="","",COUNTIF($A$54:$A$114,$A47)) | F47: =IF($A47="","",COUNTIFS($A$54:$A$114,$A47,$G$54:$G$114,"Pass")) | G47: =IF($A47="","",COUNTIFS($A$54:$A$114,$A47,$G$54:$G$114,"Fail")) | H47: =IF($A47="","",COUNTIFS($A$54:$A$114,$A47,$G$54:$G$114,"Blocked")) | I47: =IF(OR($A47="",N(E47)=0),"",F47/E47) | J47: =IF($A47="","",COUNTIFS($A$54:$A$114,$A47,$K$54:$K$114,"CHẶN")) | K47: =IF($A47="","",IF(E47=0,"Chưa có bước",IF(J47>0,"CHƯA ĐẠT",IF(F47=E47,"ĐẠT",IF(G47+H47>0,"CHƯA ĐẠT","ĐANG TEST")))))
E48: =IF($A48="","",COUNTIF($A$54:$A$114,$A48)) | F48: =IF($A48="","",COUNTIFS($A$54:$A$114,$A48,$G$54:$G$114,"Pass")) | G48: =IF($A48="","",COUNTIFS($A$54:$A$114,$A48,$G$54:$G$114,"Fail")) | H48: =IF($A48="","",COUNTIFS($A$54:$A$114,$A48,$G$54:$G$114,"Blocked")) | I48: =IF(OR($A48="",N(E48)=0),"",F48/E48) | J48: =IF($A48="","",COUNTIFS($A$54:$A$114,$A48,$K$54:$K$114,"CHẶN")) | K48: =IF($A48="","",IF(E48=0,"Chưa có bước",IF(J48>0,"CHƯA ĐẠT",IF(F48=E48,"ĐẠT",IF(G48+H48>0,"CHƯA ĐẠT","ĐANG TEST")))))
...

Sheet 04_Mục_tiêu
A1: MỤC TIÊU KPI THEO KỲ — nhập tay (ô nền vàng)
A3: MỤC TIÊU THEO THÁNG
A4: Tháng | B4: Trang hoàn thành | C4: Tính năng hoàn thành | D4: Công việc HT trong kỳ | E4: Lỗi phát hiện trong kỳ | F4: Lỗi đã xử lý (lũy kế) | G4: Số Trang đã xử lý | H4: Số Tính năng đã xử lý | I4: DB Doanh nghiệp | J4: DB HR | K4: DB Ứng viên | L4: Tin tuyển dụng
A5: 1
A6: 2
A7: 3
A8: 4
A9: 5
A10: 6
A11: 7
A12: 8
A13: 9
A14: 10
A15: 11
A16: 12
A18: MỤC TIÊU THEO TUẦN
A19: Tháng | B19: Tuần | C19: Key | D19: Trang hoàn thành | E19: Tính năng hoàn thành | F19: Công việc HT trong kỳ | G19: Lỗi phát hiện trong kỳ | H19: Lỗi đã xử lý (lũy kế) | I19: Số Trang đã xử lý | J19: Số Tính năng đã xử lý | K19: DB Doanh nghiệp | L19: DB HR | M19: DB Ứng viên | N19: Tin tuyển dụng
A20: 1 | B20: 1 | C20: =A20*10+B20
A21: 1 | B21: 2 | C21: =A21*10+B21
A22: 1 | B22: 3 | C22: =A22*10+B22
A23: 1 | B23: 4 | C23: =A23*10+B23
A24: 1 | B24: 5 | C24: =A24*10+B24
A25: 2 | B25: 1 | C25: =A25*10+B25
A26: 2 | B26: 2 | C26: =A26*10+B26
A27: 2 | B27: 3 | C27: =A27*10+B27
A28: 2 | B28: 4 | C28: =A28*10+B28
A29: 2 | B29: 5 | C29: =A29*10+B29
A30: 3 | B30: 1 | C30: =A30*10+B30
A31: 3 | B31: 2 | C31: =A31*10+B31
... A79: 12 | B79: 5 | C79: =A79*10+B79
